Workbook

Sheet Raw Data
A1: Order_ID | B1: Order_Date | C1: City | D1: Cuisine | E1: Customer_Type | F1: Payment_Method | G1: Order_Value | H1: Discount | I1: Delivery_Fee | J1: Delivery_Time_Min | K1: Rating | L1: Order_Status
A2: FD100001 | B2: 45951 | C2: Hyderabad | D2: South Indian | E2: New | F2: Credit Card | G2: 309 | H2: 0 | I2: 30 | J2: 28 | K2: 3.5 | L2: Delivered
A3: FD100002 | B3: 45835 | C3: Ahmedabad | D3: Pizza | E3: Returning | F3: UPI | G3: 517 | H3: 0 | I3: 0 | J3: 24 | K3: 4.7 | L3: Delivered
A4: FD100003 | B4: 45978 | C4: Delhi | D4: Biryani | E4: Returning | F4: Credit Card | G4: 512 | H4: 0 | I4: 0 | J4: 31 | K4: 4.2 | L4: Delivered
A5: FD100004 | B5: 45926 | C5: Bengaluru | D5: Chinese | E5: Returning | F5: UPI | G5: 491 | H5: 64 | I5: 20 | J5: 51 | K5: 3.2 | L5: Delivered
A6: FD100005 | B6: 45699 | C6: Chennai | D6: North Indian | E6: New | F6: UPI | G6: 678 | H6: 0 | I6: 0 | J6: 31 | K6: 3.8 | L6: Delivered
A7: FD100006 | B7: 46015 | C7: Bengaluru | D7: Chinese | E7: Returning | F7: Credit Card | G7: 540 | H7: 0 | I7: 0 | J7: 38 | K7: 3.7 | L7: Delivered
A8: FD100007 | B8: 45947 | C8: Hyderabad | D8: Pizza | E8: Returning | F8: Debit Card | G8: 592 | H8: 0 | I8: 0 | J8: 34 | K8: 4.7 | L8: Delivered
A9: FD100008 | B9: 45955 | C9: Bengaluru | D9: North Indian | E9: New | F9: Cash on Delivery | G9: 546 | H9: 84 | I9: 0 | J9: 47 | K9: 4.6 | L9: Delivered
A10: FD100009 | B10: 45713 | C10: Delhi | D10: North Indian | E10: Returning | F10: Cash on Delivery | G10: 393 | H10: 68 | I10: 30 | J10: 34 | K10: 5 | L10: Delivered
A11: FD100010 | B11: 45839 | C11: Hyderabad | D11: Chinese | E11: New | F11: Cash on Delivery | G11: 525 | H11: 74 | I11: 0 | J11: 39 | K11: 3.4 | L11: Delivered
A12: FD100011 | B12: 45809 | C12: Mumbai | D12: Biryani | E12: Returning | G12: 412 | H12: 0 | I12: 20 | J12: 29 | K12: 3.7 | L12: Delivered
A13: FD100012 | B13: 46000 | C13: Mumbai | D13: South Indian | E13: Returning | F13: Cash on Delivery | G13: 421 | H13: 98 | I13: 45 | J13: 46 | K13: 3.3 | L13: Delivered
A14: FD100013 | B14: 45907 | C14: Hyderabad | D14: Chinese | E14: Returning | F14: UPI | G14: 430 | H14: 0 | I14: 20 | J14: 33 | K14: 5 | L14: Delivered
A15: FD100014 | B15: 45967 | C15: Hyderabad | D15: Chinese | E15: New | F15: Debit Card | G15: 268 | H15: 38 | I15: 20 | J15: 33 | K15: 4.5 | L15: Delivered
A16: FD100015 | B16: 45836 | C16: Pune | D16: Biryani | E16: New | F16: UPI | G16: 366 | H16: 40 | I16: 45 | J16: 25 | K16: 4.6 | L16: Delivered
A17: FD100016 | B17: 45754 | C17: Delhi | D17: Chinese | E17: New | F17: UPI | G17: 337 | H17: 41 | I17: 30 | J17: 27 | K17: 4.6 | L17: Delivered
A18: FD100017 | B18: 45877 | C18: Mumbai | D18: Healthy | E18: Returning | F18: UPI | G18: 379 | H18: 70 | I18: 40 | J18: 26 | K18: 4.5 | L18: Delivered
A19: FD100018 | B19: 45686 | C19: Kolkata | D19: North Indian | E19: New | F19: Cash on Delivery | G19: 540 | H19: 0 | I19: 0 | J19: 30 | K19: 3.8 | L19: Delivered
A20: FD100019 | B20: 45968 | C20: Mumbai | D20: Biryani | E20: Returning | F20: Cash on Delivery | G20: 566 | H20: 0 | I20: 0 | J20: 42 | K20: 4.4 | L20: Delivered
A21: FD100020 | B21: 45903 | C21: Mumbai | D21: Biryani | E21: New | F21: Wallet | G21: 315 | H21: 40 | I21: 30 | J21: 31 | K21: 4.3 | L21: Delivered
A22: FD100021 | B22: 45946 | C22: Delhi | D22: Fast Food | E22: New | F22: Wallet | G22: 315 | H22: 47 | I22: 30 | J22: 25 | K22: 3.9 | L22: Delivered
A23: FD100022 | B23: 45803 | C23: Bengaluru | D23: Chinese | E23: returning | F23: Wallet | G23: 358 | H23: 0 | I23: 45 | J23: 36 | K23: 4.5 | L23: Delivered
A24: FD100023 | B24: 46013 | C24: Pune | D24: Fast Food | E24: Returning | F24: UPI | G24: 220 | H24: 0 | I24: 40 | J24: 27 | K24: 4.3 | L24: Delivered
... A27: FD100026 | B27: 45741 | C27: Mumbai | D27: North Indian | E27: Returning | F27: Wallet | G27: 455 | H27: 70 | I27: 30 | J27: 45 | K27: 4.5 | L27: Delivered
A28: FD100027 | B28: 07-07-2025 | C28: Delhi | D28: Biryani | E28: Returning | F28: UPI | G28: 382 | H28: 46 | I28: 45 | J28: 45 | K28: 4.1 | L28: Delivered
A29: FD100028 | B29: 45677 | C29: Bengaluru | D29: South Indian | E29: Returning | F29: UPI | G29: 367 | H29: 0 | I29: 40 | L29: Cancelled
A30: FD100029 | B30: 45724 | C30: Mumbai | D30: Pizza | E30: New | F30: Wallet | G30: 617 | H30: 0 | I30: 0 | J30: 27 | K30: 4.6 | L30: Delivered
A31: FD100030 | B31: 45920 | C31: DELHI | D31: Fast Food | E31: Returning | F31: UPI | G31: 454 | H31: 0 | I31: 30 | L31: Cancelled
A32: FD100031 | B32: 45941 | C32: Delhi | D32: Chinese | E32: Returning | F32: UPI | G32: 374 | H32: 43 | I32: 40 | J32: 41 | K32: 4.4 | L32: Delivered
A33: FD100032 | B33: 46012 | C33: Mumbai | D33: North Indian | E33: New | F33: Credit Card | G33: 351 | H33: 67 | I33: 20 | J33: 35 | K33: 4.8 | L33: Delivered
A34: FD100033 | B34: 45793 | C34: Bengaluru | D34: Biryani | E34: Returning | F34: UPI | H34: 0 | I34: 20 | J34: 48 | K34: 3.6 | L34: Delivered
A35: FD100034 | B35: 45809 | C35: Hyderabad | D35: Biryani | E35: Returning | F35: UPI | G35: 518 | H35: 58 | I35: 0 | J35: 34 | K35: 4.6 | L35: Delivered
A36: FD100035 | B36: 45846 | C36: Mumbai | D36: Desserts | E36: Returning | F36: Wallet | G36: 417 | H36: 0 | I36: 40 | J36: 49 | K36: 3.1 | L36: Delivered
A37: FD100036 | B37: 45738 | C37: Bengaluru | D37: Chinese | E37: New | F37: Wallet | G37: 312 | H37: 0 | I37: 30 | J37: 49 | K37: 3.9 | L37: Delivered
A38: FD100037 | B38: 45714 | C38: Chennai | D38: Pizza | E38: Returning | F38: Wallet | G38: 750 | H38: 183 | I38: 0 | J38: 38 | K38: 4.1 | L38: Delivered
A39: FD100038 | B39: 45848 | C39: Hyderabad | D39: North Indian | E39: Returning | F39: UPI | G39: 508 | H39: 0 | I39: 0 | J39: 30 | K39: 5 | L39: Delivered
A40: FD100039 | B40: 45753 | C40: Chennai | D40: North Indian | E40: New | F40: UPI | G40: 475 | H40: 78 | I40: 30 | J40: 30 | L40: Delivered
A41: FD100040 | B41: 45916 | C41: Bengaluru | D41: Pizza | E41: Returning | F41: Credit Card | G41: 832 | H41: 0 | I41: 0 | J41: 40 | K41: 4.5 | L41: Delivered
A42: FD100041 | B42: 45834 | C42: Chennai | D42: Fast Food | E42: New | F42: Credit Card | G42: 416 | H42: 94 | I42: 40 | J42: 20 | K42: 3.8 | L42: Delivered
...

Sheet Cleaned Data
A1: Order_ID | B1: Order_Date | C1: Month | D1: Weekday | E1: City | F1: Cuisine | G1: Customer_Type | H1: Payment_Method | I1: Order_Value | J1: Discount | K1: Delivery_Fee | L1: Net_Revenue | M1: Delivery_Time_Min | N1: Rating | O1: Order_Status
A2: FD100741 | B2: 45658 | C2: =TEXT(B2,"mmm") -> Jan | D2: =TEXT(B2,"ddd") -> Wed | E2: Delhi | F2: Biryani | G2: New | H2: Debit Card | I2: 310 | J2: 74 | K2: 40 | L2: =IF(O2="Delivered",I2-J2+K2,0) -> 276 | M2: 30 | N2: 5 | O2: Delivered
A3: FD100744 | B3: 45658 | C3: =TEXT(B3,"mmm") -> Jan | D3: =TEXT(B3,"ddd") -> Wed | E3: Delhi | F3: Fast Food | G3: New | H3: UPI | I3: 353 | J3: 54 | K3: 40 | L3: =IF(O3="Delivered",I3-J3+K3,0) -> 339 | M3: 46 | N3: 3.3 | O3: Delivered
A4: FD101158 | B4: 45658 | C4: =TEXT(B4,"mmm") -> Jan | D4: =TEXT(B4,"ddd") -> Wed | E4: Bengaluru | F4: North Indian | G4: Returning | H4: Wallet | I4: 408 | J4: 53 | K4: 20 | L4: =IF(O4="Delivered",I4-J4+K4,0) -> 375 | M4: 50 | N4: 3.5 | O4: Delivered
A5: FD101221 | B5: 45658 | C5: =TEXT(B5,"mmm") -> Jan | D5: =TEXT(B5,"ddd") -> Wed | E5: Bengaluru | F5: North Indian | G5: Returning | H5: UPI | I5: 531 | J5: 0 | K5: 0 | L5: =IF(O5="Delivered",I5-J5+K5,0) -> 531 | M5: 52 | N5: 2.8 | O5: Delivered
A6: FD100423 | B6: 45660 | C6: =TEXT(B6,"mmm") -> Jan | D6: =TEXT(B6,"ddd") -> Fri | E6: Bengaluru | F6: Pizza | G6: New | H6: Debit Card | I6: 805 | J6: 0 | K6: 0 | L6: =IF(O6="Delivered",I6-J6+K6,0) -> 0 | O6: Cancelled
A7: FD100647 | B7: 45660 | C7: =TEXT(B7,"mmm") -> Jan | D7: =TEXT(B7,"ddd") -> Fri | E7: Mumbai | F7: Biryani | G7: Returning | H7: UPI | I7: 369 | J7: 56 | K7: 45 | L7: =IF(O7="Delivered",I7-J7+K7,0) -> 358 | M7: 32 | N7: 4.5 | O7: Delivered
A8: FD100775 | B8: 45660 | C8: =TEXT(B8,"mmm") -> Jan | D8: =TEXT(B8,"ddd") -> Fri | E8: Pune | F8: South Indian | G8: Returning | H8: Credit Card | I8: 347 | J8: 0 | K8: 30 | L8: =IF(O8="Delivered",I8-J8+K8,0) -> 377 | M8: 35 | N8: 4.3 | O8: Delivered
A9: FD100811 | B9: 45660 | C9: =TEXT(B9,"mmm") -> Jan | D9: =TEXT(B9,"ddd") -> Fri | E9: Ahmedabad | F9: Pizza | G9: Returning | H9: UPI | I9: 374 | J9: 0 | K9: 30 | L9: =IF(O9="Delivered",I9-J9+K9,0) -> 404 | M9: 32 | N9: 4.7 | O9: Delivered
A10: FD101314 | B10: 45660 | C10: =TEXT(B10,"mmm") -> Jan | D10: =TEXT(B10,"ddd") -> Fri | E10: Mumbai | F10: South Indian | G10: Returning | H10: Debit Card | I10: 301 | J10: 73 | K10: 20 | L10: =IF(O10="Delivered",I10-J10+K10,0) -> 248 | M10: 23 | N10: 5 | O10: Delivered
A11: FD101323 | B11: 45660 | C11: =TEXT(B11,"mmm") -> Jan | D11: =TEXT(B11,"ddd") -> Fri | E11: Mumbai | F11: Pizza | G11: Returning | H11: UPI | I11: 693 | J11: 0 | K11: 0 | L11: =IF(O11="Delivered",I11-J11+K11,0) -> 693 | M11: 40 | N11: 5 | O11: Delivered
A12: FD100052 | B12: 45661 | C12: =TEXT(B12,"mmm") -> Jan | D12: =TEXT(B12,"ddd") -> Sat | E12: Bengaluru | F12: North Indian | G12: Returning | H12: Credit Card | I12: 423 | J12: 0 | K12: 20 | L12: =IF(O12="Delivered",I12-J12+K12,0) -> 443 | M12: 45 | N12: 2.9 | O12: Delivered
A13: FD100595 | B13: 45661 | C13: =TEXT(B13,"mmm") -> Jan | D13: =TEXT(B13,"ddd") -> Sat | E13: Pune | F13: North Indian | G13: Returning | H13: Wallet | I13: 431 | J13: 0 | K13: 20 | L13: =IF(O13="Delivered",I13-J13+K13,0) -> 451 | M13: 26 | N13: 5 | O13: Delivered
A14: FD101101 | B14: 45661 | C14: =TEXT(B14,"mmm") -> Jan | D14: =TEXT(B14,"ddd") -> Sat | E14: Bengaluru | F14: Biryani | G14: Returning | H14: UPI | I14: 364 | J14: 0 | K14: 45 | L14: =IF(O14="Delivered",I14-J14+K14,0) -> 409 | M14: 54 | N14: 3.7 | O14: Delivered
A15: FD100535 | B15: 45662 | C15: =TEXT(B15,"mmm") -> Jan | D15: =TEXT(B15,"ddd") -> Sun | E15: Mumbai | F15: Chinese | G15: Returning | H15: Credit Card | I15: 478 | J15: 94 | K15: 40 | L15: =IF(O15="Delivered",I15-J15+K15,0) -> 424 | M15: 33 | N15: 4.5 | O15: Delivered
A16: FD100766 | B16: 45662 | C16: =TEXT(B16,"mmm") -> Jan | D16: =TEXT(B16,"ddd") -> Sun | E16: Mumbai | F16: South Indian | G16: New | H16: Debit Card | I16: 261 | J16: 28 | K16: 30 | L16: =IF(O16="Delivered",I16-J16+K16,0) -> 263 | M16: 37 | N16: 4.6 | O16: Delivered
A17: FD100395 | B17: 45663 | C17: =TEXT(B17,"mmm") -> Jan | D17: =TEXT(B17,"ddd") -> Mon | E17: Delhi | F17: Chinese | G17: Returning | H17: Debit Card | I17: 270 | J17: 0 | K17: 45 | L17: =IF(O17="Delivered",I17-J17+K17,0) -> 315 | M17: 33 | N17: 3.8 | O17: Delivered
A18: FD100841 | B18: 45663 | C18: =TEXT(B18,"mmm") -> Jan | D18: =TEXT(B18,"ddd") -> Mon | E18: Mumbai | F18: Chinese | G18: New | H18: Cash on Delivery | I18: 413 | J18: 72 | K18: 45 | L18: =IF(O18="Delivered",I18-J18+K18,0) -> 386 | M18: 41 | N18: 3.5 | O18: Delivered
... A24: FD100797 | B24: 45666 | C24: =TEXT(B24,"mmm") -> Jan | D24: =TEXT(B24,"ddd") -> Thu | E24: Hyderabad | F24: Pizza | G24: Returning | H24: Cash on Delivery | I24: 713 | J24: 0 | K24: 0 | L24: =IF(O24="Delivered",I24-J24+K24,0) -> 713 | M24: 35 | N24: 3.9 | O24: Delivered
A25: FD100826 | B25: 45666 | C25: =TEXT(B25,"mmm") -> Jan | D25: =TEXT(B25,"ddd") -> Thu | E25: Ahmedabad | F25: Pizza | G25: New | H25: Credit Card | I25: 670 | J25: 0 | K25: 0 | L25: =IF(O25="Delivered",I25-J25+K25,0) -> 670 | M25: 30 | O25: Delivered
A26: FD101045 | B26: 45666 | C26: =TEXT(B26,"mmm") -> Jan | D26: =TEXT(B26,"ddd") -> Thu | E26: Bengaluru | F26: Fast Food | G26: Returning | H26: Wallet | I26: 291 | J26: 58 | K26: 40 | L26: =IF(O26="Delivered",I26-J26+K26,0) -> 273 | M26: 28 | N26: 4.8 | O26: Delivered
A27: FD100150 | B27: 45667 | C27: =TEXT(B27,"mmm") -> Jan | D27: =TEXT(B27,"ddd") -> Fri | E27: Chennai | F27: North Indian | G27: Returning | H27: Cash on Delivery | I27: 564 | J27: 0 | K27: 0 | L27: =IF(O27="Delivered",I27-J27+K27,0) -> 564 | M27: 24 | N27: 4.2 | O27: Delivered
A28: FD100270 | B28: 45667 | C28: =TEXT(B28,"mmm") -> Jan | D28: =TEXT(B28,"ddd") -> Fri | E28: Chennai | F28: North Indian | G28: Returning | H28: Unknown | I28: 675 | J28: 0 | K28: 0 | L28: =IF(O28="Delivered",I28-J28+K28,0) -> 675 | M28: 31 | O28: Delivered
A29: FD100085 | B29: 45668 | C29: =TEXT(B29,"mmm") -> Jan | D29: =TEXT(B29,"ddd") -> Sat | E29: Bengaluru | F29: Chinese | G29: Returning | H29: UPI | I29: 548 | J29: 0 | K29: 0 | L29: =IF(O29="Delivered",I29-J29+K29,0) -> 548 | M29: 41 | N29: 5 | O29: Delivered
A30: FD100136 | B30: 45668 | C30: =TEXT(B30,"mmm") -> Jan | D30: =TEXT(B30,"ddd") -> Sat | E30: Bengaluru | F30: Chinese | G30: New | H30: UPI | I30: 465 | J30: 0 | K30: 45 | L30: =IF(O30="Delivered",I30-J30+K30,0) -> 510 | M30: 29 | O30: Delivered
A31: FD100227 | B31: 45668 | C31: =TEXT(B31,"mmm") -> Jan | D31: =TEXT(B31,"ddd") -> Sat | E31: Delhi | F31: Chinese | G31: Returning | H31: Credit Card | I31: 460 | J31: 0 | K31: 20 | L31: =IF(O31="Delivered",I31-J31+K31,0) -> 480 | M31: 31 | O31: Delivered
A32: FD100590 | B32: 45668 | C32: =TEXT(B32,"mmm") -> Jan | D32: =TEXT(B32,"ddd") -> Sat | E32: Bengaluru | F32: Biryani | G32: New | H32: Credit Card | I32: 315 | J32: 0 | K32: 45 | L32: =IF(O32="Delivered",I32-J32+K32,0) -> 360 | M32: 41 | O32: Delivered
A33: FD100872 | B33: 45668 | C33: =TEXT(B33,"mmm") -> Jan | D33: =TEXT(B33,"ddd") -> Sat | E33: Delhi | F33: Biryani | G33: Returning | H33: Credit Card | I33: 491 | J33: 0 | K33: 30 | L33: =IF(O33="Delivered",I33-J33+K33,0) -> 521 | M33: 32 | N33: 5 | O33: Delivered
A34: FD101069 | B34: 45668 | C34: =TEXT(B34,"mmm") -> Jan | D34: =TEXT(B34,"ddd") -> Sat | E34: Hyderabad | F34: Healthy | G34: New | H34: Credit Card | I34: 477 | J34: 81 | K34: 30 | L34: =IF(O34="Delivered",I34-J34+K34,0) -> 426 | M34: 35 | N34: 4.3 | O34: Delivered
A35: FD101356 | B35: 45668 | C35: =TEXT(B35,"mmm") -> Jan | D35: =TEXT(B35,"ddd") -> Sat | E35: Kolkata | F35: Chinese | G35: Returning | H35: UPI | I35: 505 | J35: 108 | K35: 0 | L35: =IF(O35="Delivered",I35-J35+K35,0) -> 397 | M35: 30 | N35: 5 | O35: Delivered
A36: FD101205 | B36: 45669 | C36: =TEXT(B36,"mmm") -> Jan | D36: =TEXT(B36,"ddd") -> Sun | E36: Hyderabad | F36: Chinese | G36: Returning | H36: Debit Card | I36: 520 | J36: 0 | K36: 0 | L36: =IF(O36="Delivered",I36-J36+K36,0) -> 520 | M36: 19 | N36: 4.5 | O36: Delivered
A37: FD101318 | B37: 45669 | C37: =TEXT(B37,"mmm") -> Jan | D37: =TEXT(B37,"ddd") -> Sun | E37: Bengaluru | F37: Chinese | G37: New | H37: Wallet | I37: 520 | J37: 79 | K37: 0 | L37: =IF(O37="Delivered",I37-J37+K37,0) -> 441 | M37: 35 | N37: 4.3 | O37: Delivered
A38: FD100415 | B38: 45670 | C38: =TEXT(B38,"mmm") -> Jan | D38: =TEXT(B38,"ddd") -> Mon | E38: Mumbai | F38: Biryani | G38: New | H38: Credit Card | I38: 551 | J38: 115 | K38: 0 | L38: =IF(O38="Delivered",I38-J38+K38,0) -> 436 | M38: 36 | N38: 5 | O38: Delivered
A39: FD100650 | B39: 45670 | C39: =TEXT(B39,"mmm") -> Jan | D39: =TEXT(B39,"ddd") -> Mon | E39: Mumbai | F39: South Indian | G39: New | H39: UPI | I39: 228 | J39: 0 | K39: 20 | L39: =IF(O39="Delivered",I39-J39+K39,0) -> 248 | M39: 38 | N39: 4.1 | O39: Delivered
A40: FD100069 | B40: 45671 | C40: =TEXT(B40,"mmm") -> Jan | D40: =TEXT(B40,"ddd") -> Tue | E40: Bengaluru | F40: Chinese | G40: Returning | H40: UPI | I40: 430 | J40: 0 | K40: 45 | L40: =IF(O40="Delivered",I40-J40+K40,0) -> 475 | M40: 41 | N40: 4.9 | O40: Delivered
A41: FD100768 | B41: 45671 | C41: =TEXT(B41,"mmm") -> Jan | D41: =TEXT(B41,"ddd") -> Tue | E41: Bengaluru | F41: Biryani | G41: Returning | H41: Credit Card | I41: 536 | J41: 0 | K41: 0 | L41: =IF(O41="Delivered",I41-J41+K41,0) -> 536 | M41: 32 | N41: 4.4 | O41: Delivered
A42: FD100795 | B42: 45671 | C42: =TEXT(B42,"mmm") -> Jan | D42: =TEXT(B42,"ddd") -> Tue | E42: Delhi | F42: Pizza | G42: Returning | H42: Debit Card | I42: 491 | J42: 58 | K42: 20 | L42: =IF(O42="Delivered",I42-J42+K42,0) -> 453 | M42: 39 | N42: 4.2 | O42: Delivered
A43: FD100972 | B43: 45671 | C43: =TEXT(B43,"mmm") -> Jan | D43: =TEXT(B43,"ddd") -> Tue | E43: Pune | F43: North Indian | G43: New | H43: UPI | I43: 579 | J43: 103 | K43: 0 | L43: =IF(O43="Delivered",I43-J43+K43,0) -> 476 | M43: 12 | N43: 4.5 | O43: Delivered
A44: FD101161 | B44: 45673 | C44: =TEXT(B44,"mmm") -> Jan | D44: =TEXT(B44,"ddd") -> Thu | E44: Pune | F44: Fast Food | G44: Returning | H44: Debit Card | I44: 396 | J44: 0 | K44: 40 | L44: =IF(O44="Delivered",I44-J44+K44,0) -> 436 | M44: 36 | N44: 4.3 | O44: Delivered
... A58: FD100451 | B58: 45676 | C58: =TEXT(B58,"mmm") -> Jan | D58: =TEXT(B58,"ddd") -> Sun | E58: Kolkata | F58: Chinese | G58: New | H58: UPI | I58: 573 | J58: 0 | K58: 0 | L58: =IF(O58="Delivered",I58-J58+K58,0) -> 573 | M58: 30 | N58: 4.5 | O58: Delivered
...

Sheet Pivot Tables
A1: PIVOT-STYLE SUMMARY TABLES (live formulas on tblOrders – respond to Dashboard filters)
A3: City filter | B3: =IF(Dashboard!$C$4="All","*",Dashboard!$C$4) -> * | C3: ← criteria driven by Dashboard dropdowns ('*' = All)
A4: Cuisine filter | B4: =IF(Dashboard!$C$5="All","*",Dashboard!$C$5) -> *
A5: Customer filter | B5: =IF(Dashboard!$C$6="All","*",Dashboard!$C$6) -> *
A7: PIVOT 1 – Sales by City
A8: City | B8: Orders | C8: Net Revenue (₹) | D8: Avg Order Value (₹) | E8: Avg Delivery Time (min) | F8: Avg Rating
A9: Mumbai | B9: =COUNTIFS('Cleaned Data'!$E$2:$E$1489,$B$3,'Cleaned Data'!$F$2:$F$1489,$B$4,'Cleaned Data'!$G$2:$G$1489,$B$5,'Cleaned Data'!$O$2:$O$1489,"Delivered",'Cleaned Data'!$E$2:$E$1489,$A9) -> 276 | C9: =SUMIFS('Cleaned Data'!$L$2:$L$1489,'Cleaned Data'!$E$2:$E$1489,$B$3,'Cleaned Data'!$F$2:$F$1489,$B$4,'Cleaned Data'!$G$2:$G$1489,$B$5,'Cleaned Data'!$O$2:$O$1489,"Delivered",'Cleaned Data'!$E$2:$E$1489,$A9) -> 121927 | D9: =IFERROR(C9/B9,0) -> 441.76449 | E9: =IFERROR(AVERAGEIFS('Cleaned Data'!$M$2:$M$1489,'Cleaned Data'!$E$2:$E$1489,$B$3,'Cleaned Data'!$F$2:$F$1489,$B$4,'Cleaned Data'!$G$2:$G$1489,$B$5,'Cleaned Data'!$O$2:$O$1489,"Delivered",'Cleaned Data'!$E$2:$E$1489,$A9),0) -> 37.985507 | F9: =IFERROR(AVERAGEIFS('Cleaned Data'!$N$2:$N$1489,'Cleaned Data'!$E$2:$E$1489,$B$3,'Cleaned Data'!$F$2:$F$1489,$B$4,'Cleaned Data'!$G$2:$G$1489,$B$5,'Cleaned Data'!$O$2:$O$1489,"Delivered",'Cleaned Data'!$E$2:$E$1489,$A9),0) -> 4.2876448
A10: Delhi | B10: =COUNTIFS('Cleaned Data'!$E$2:$E$1489,$B$3,'Cleaned Data'!$F$2:$F$1489,$B$4,'Cleaned Data'!$G$2:$G$1489,$B$5,'Cleaned Data'!$O$2:$O$1489,"Delivered",'Cleaned Data'!$E$2:$E$1489,$A10) -> 280 | C10: =SUMIFS('Cleaned Data'!$L$2:$L$1489,'Cleaned Data'!$E$2:$E$1489,$B$3,'Cleaned Data'!$F$2:$F$1489,$B$4,'Cleaned Data'!$G$2:$G$1489,$B$5,'Cleaned Data'!$O$2:$O$1489,"Delivered",'Cleaned Data'!$E$2:$E$1489,$A10) -> 128254 | D10: =IFERROR(C10/B10,0) -> 458.05 | E10: =IFERROR(AVERAGEIFS('Cleaned Data'!$M$2:$M$1489,'Cleaned Data'!$E$2:$E$1489,$B$3,'Cleaned Data'!$F$2:$F$1489,$B$4,'Cleaned Data'!$G$2:$G$1489,$B$5,'Cleaned Data'!$O$2:$O$1489,"Delivered",'Cleaned Data'!$E$2:$E$1489,$A10),0) -> 36.107143 | F10: =IFERROR(AVERAGEIFS('Cleaned Data'!$N$2:$N$1489,'Cleaned Data'!$E$2:$E$1489,$B$3,'Cleaned Data'!$F$2:$F$1489,$B$4,'Cleaned Data'!$G$2:$G$1489,$B$5,'Cleaned Data'!$O$2:$O$1489,"Delivered",'Cleaned Data'!$E$2:$E$1489,$A10),0) -> 4.2350943
A11: Bengaluru | B11: =COUNTIFS('Cleaned Data'!$E$2:$E$1489,$B$3,'Cleaned Data'!$F$2:$F$1489,$B$4,'Cleaned Data'!$G$2:$G$1489,$B$5,'Cleaned Data'!$O$2:$O$1489,"Delivered",'Cleaned Data'!$E$2:$E$1489,$A11) -> 319 | C11: =SUMIFS('Cleaned Data'!$L$2:$L$1489,'Cleaned Data'!$E$2:$E$1489,$B$3,'Cleaned Data'!$F$2:$F$1489,$B$4,'Cleaned Data'!$G$2:$G$1489,$B$5,'Cleaned Data'!$O$2:$O$1489,"Delivered",'Cleaned Data'!$E$2:$E$1489,$A11) -> 141596 | D11: =IFERROR(C11/B11,0) -> 443.87461 | E11: =IFERROR(AVERAGEIFS('Cleaned Data'!$M$2:$M$1489,'Cleaned Data'!$E$2:$E$1489,$B$3,'Cleaned Data'!$F$2:$F$1489,$B$4,'Cleaned Data'!$G$2:$G$1489,$B$5,'Cleaned Data'!$O$2:$O$1489,"Delivered",'Cleaned Data'!$E$2:$E$1489,$A11),0) -> 41.912226 | F11: =IFERROR(AVERAGEIFS('Cleaned Data'!$N$2:$N$1489,'Cleaned Data'!$E$2:$E$1489,$B$3,'Cleaned Data'!$F$2:$F$1489,$B$4,'Cleaned Data'!$G$2:$G$1489,$B$5,'Cleaned Data'!$O$2:$O$1489,"Delivered",'Cleaned Data'!$E$2:$E$1489,$A11),0) -> 4.1192691
A12: Hyderabad | B12: =COUNTIFS('Cleaned Data'!$E$2:$E$1489,$B$3,'Cleaned Data'!$F$2:$F$1489,$B$4,'Cleaned Data'!$G$2:$G$1489,$B$5,'Cleaned Data'!$O$2:$O$1489,"Delivered",'Cleaned Data'!$E$2:$E$1489,$A12) -> 185 | C12: =SUMIFS('Cleaned Data'!$L$2:$L$1489,'Cleaned Data'!$E$2:$E$1489,$B$3,'Cleaned Data'!$F$2:$F$1489,$B$4,'Cleaned Data'!$G$2:$G$1489,$B$5,'Cleaned Data'!$O$2:$O$1489,"Delivered",'Cleaned Data'!$E$2:$E$1489,$A12) -> 82386 | D12: =IFERROR(C12/B12,0) -> 445.32973 | E12: =IFERROR(AVERAGEIFS('Cleaned Data'!$M$2:$M$1489,'Cleaned Data'!$E$2:$E$1489,$B$3,'Cleaned Data'!$F$2:$F$1489,$B$4,'Cleaned Data'!$G$2:$G$1489,$B$5,'Cleaned Data'!$O$2:$O$1489,"Delivered",'Cleaned Data'!$E$2:$E$1489,$A12),0) -> 32.881081 | F12: =IFERROR(AVERAGEIFS('Cleaned Data'!$N$2:$N$1489,'Cleaned Data'!$E$2:$E$1489,$B$3,'Cleaned Data'!$F$2:$F$1489,$B$4,'Cleaned Data'!$G$2:$G$1489,$B$5,'Cleaned Data'!$O$2:$O$1489,"Delivered",'Cleaned Data'!$E$2:$E$1489,$A12),0) -> 4.3011364
A13: Chennai | B13: =COUNTIFS('Cleaned Data'!$E$2:$E$1489,$B$3,'Cleaned Data'!$F$2:$F$1489,$B$4,'Cleaned Data'!$G$2:$G$1489,$B$5,'Cleaned Data'!$O$2:$O$1489,"Delivered",'Cleaned Data'!$E$2:$E$1489,$A13) -> 109 | C13: =SUMIFS('Cleaned Data'!$L$2:$L$1489,'Cleaned Data'!$E$2:$E$1489,$B$3,'Cleaned Data'!$F$2:$F$1489,$B$4,'Cleaned Data'!$G$2:$G$1489,$B$5,'Cleaned Data'!$O$2:$O$1489,"Delivered",'Cleaned Data'!$E$2:$E$1489,$A13) -> 48378 | D13: =IFERROR(C13/B13,0) -> 443.83486 | E13: =IFERROR(AVERAGEIFS('Cleaned Data'!$M$2:$M$1489,'Cleaned Data'!$E$2:$E$1489,$B$3,'Cleaned Data'!$F$2:$F$1489,$B$4,'Cleaned Data'!$G$2:$G$1489,$B$5,'Cleaned Data'!$O$2:$O$1489,"Delivered",'Cleaned Data'!$E$2:$E$1489,$A13),0) -> 31.385321 | F13: =IFERROR(AVERAGEIFS('Cleaned Data'!$N$2:$N$1489,'Cleaned Data'!$E$2:$E$1489,$B$3,'Cleaned Data'!$F$2:$F$1489,$B$4,'Cleaned Data'!$G$2:$G$1489,$B$5,'Cleaned Data'!$O$2:$O$1489,"Delivered",'Cleaned Data'!$E$2:$E$1489,$A13),0) -> 4.3773196
A14: Pune | B14: =COUNTIFS('Cleaned Data'!$E$2:$E$1489,$B$3,'Cleaned Data'!$F$2:$F$1489,$B$4,'Cleaned Data'!$G$2:$G$1489,$B$5,'Cleaned Data'!$O$2:$O$1489,"Delivered",'Cleaned Data'!$E$2:$E$1489,$A14) -> 103 | C14: =SUMIFS('Cleaned Data'!$L$2:$L$1489,'Cleaned Data'!$E$2:$E$1489,$B$3,'Cleaned Data'!$F$2:$F$1489,$B$4,'Cleaned Data'!$G$2:$G$1489,$B$5,'Cleaned Data'!$O$2:$O$1489,"Delivered",'Cleaned Data'!$E$2:$E$1489,$A14) -> 44264 | D14: =IFERROR(C14/B14,0) -> 429.74757 | E14: =IFERROR(AVERAGEIFS('Cleaned Data'!$M$2:$M$1489,'Cleaned Data'!$E$2:$E$1489,$B$3,'Cleaned Data'!$F$2:$F$1489,$B$4,'Cleaned Data'!$G$2:$G$1489,$B$5,'Cleaned Data'!$O$2:$O$1489,"Delivered",'Cleaned Data'!$E$2:$E$1489,$A14),0) -> 29.679612 | F14: =IFERROR(AVERAGEIFS('Cleaned Data'!$N$2:$N$1489,'Cleaned Data'!$E$2:$E$1489,$B$3,'Cleaned Data'!$F$2:$F$1489,$B$4,'Cleaned Data'!$G$2:$G$1489,$B$5,'Cleaned Data'!$O$2:$O$1489,"Delivered",'Cleaned Data'!$E$2:$E$1489,$A14),0) -> 4.3514851
A15: Kolkata | B15: =COUNTIFS('Cleaned Data'!$E$2:$E$1489,$B$3,'Cleaned Data'!$F$2:$F$1489,$B$4,'Cleaned Data'!$G$2:$G$1489,$B$5,'Cleaned Data'!$O$2:$O$1489,"Delivered",'Cleaned Data'!$E$2:$E$1489,$A15) -> 75 | C15: =SUMIFS('Cleaned Data'!$L$2:$L$1489,'Cleaned Data'!$E$2:$E$1489,$B$3,'Cleaned Data'!$F$2:$F$1489,$B$4,'Cleaned Data'!$G$2:$G$1489,$B$5,'Cleaned Data'!$O$2:$O$1489,"Delivered",'Cleaned Data'!$E$2:$E$1489,$A15) -> 32648 | D15: =IFERROR(C15/B15,0) -> 435.30667 | E15: =IFERROR(AVERAGEIFS('Cleaned Data'!$M$2:$M$1489,'Cleaned Data'!$E$2:$E$1489,$B$3,'Cleaned Data'!$F$2:$F$1489,$B$4,'Cleaned Data'!$G$2:$G$1489,$B$5,'Cleaned Data'!$O$2:$O$1489,"Delivered",'Cleaned Data'!$E$2:$E$1489,$A15),0) -> 34.826667 | F15: =IFERROR(AVERAGEIFS('Cleaned Data'!$N$2:$N$1489,'Cleaned Data'!$E$2:$E$1489,$B$3,'Cleaned Data'!$F$2:$F$1489,$B$4,'Cleaned Data'!$G$2:$G$1489,$B$5,'Cleaned Data'!$O$2:$O$1489,"Delivered",'Cleaned Data'!$E$2:$E$1489,$A15),0) -> 4.2690141
A16: Ahmedabad | B16: =COUNTIFS('Cleaned Data'!$E$2:$E$1489,$B$3,'Cleaned Data'!$F$2:$F$1489,$B$4,'Cleaned Data'!$G$2:$G$1489,$B$5,'Cleaned Data'!$O$2:$O$1489,"Delivered",'Cleaned Data'!$E$2:$E$1489,$A16) -> 58 | C16: =SUMIFS('Cleaned Data'!$L$2:$L$1489,'Cleaned Data'!$E$2:$E$1489,$B$3,'Cleaned Data'!$F$2:$F$1489,$B$4,'Cleaned Data'!$G$2:$G$1489,$B$5,'Cleaned Data'!$O$2:$O$1489,"Delivered",'Cleaned Data'!$E$2:$E$1489,$A16) -> 25818 | D16: =IFERROR(C16/B16,0) -> 445.13793 | E16: =IFERROR(AVERAGEIFS('Cleaned Data'!$M$2:$M$1489,'Cleaned Data'!$E$2:$E$1489,$B$3,'Cleaned Data'!$F$2:$F$1489,$B$4,'Cleaned Data'!$G$2:$G$1489,$B$5,'Cleaned Data'!$O$2:$O$1489,"Delivered",'Cleaned Data'!$E$2:$E$1489,$A16),0) -> 27.810345 | F16: =IFERROR(AVERAGEIFS('Cleaned Data'!$N$2:$N$1489,'Cleaned Data'!$E$2:$E$1489,$B$3,'Cleaned Data'!$F$2:$F$1489,$B$4,'Cleaned Data'!$G$2:$G$1489,$B$5,'Cleaned Data'!$O$2:$O$1489,"Delivered",'Cleaned Data'!$E$2:$E$1489,$A16),0) -> 4.454386
A17: Grand Total | B17: =SUM(B9:B16) -> 1405 | C17: =SUM(C9:C16) -> 625271 | D17: =IFERROR(C17/B17,0) -> 445.03274 | E17: =IFERROR(AVERAGE(E9:E16),0) -> 34.073488 | F17: =IFERROR(AVERAGE(F9:F16),0) -> 4.2994187
A20: PIVOT 2 – Sales by Cuisine
A21: Cuisine | B21: Orders | C21: Net Revenue (₹) | D21: Avg Order Value (₹)
A22: North Indian | B22: =COUNTIFS('Cleaned Data'!$E$2:$E$1489,$B$3,'Cleaned Data'!$F$2:$F$1489,$B$4,'Cleaned Data'!$G$2:$G$1489,$B$5,'Cleaned Data'!$O$2:$O$1489,"Delivered",'Cleaned Data'!$F$2:$F$1489,$A22) -> 293 | C22: =SUMIFS('Cleaned Data'!$L$2:$L$1489,'Cleaned Data'!$E$2:$E$1489,$B$3,'Cleaned Data'!$F$2:$F$1489,$B$4,'Cleaned Data'!$G$2:$G$1489,$B$5,'Cleaned Data'!$O$2:$O$1489,"Delivered",'Cleaned Data'!$F$2:$F$1489,$A22) -> 139535 | D22: =IFERROR(C22/B22,0) -> 476.22867
A23: Biryani | B23: =COUNTIFS('Cleaned Data'!$E$2:$E$1489,$B$3,'Cleaned Data'!$F$2:$F$1489,$B$4,'Cleaned Data'!$G$2:$G$1489,$B$5,'Cleaned Data'!$O$2:$O$1489,"Delivered",'Cleaned Data'!$F$2:$F$1489,$A23) -> 240 | C23: =SUMIFS('Cleaned Data'!$L$2:$L$1489,'Cleaned Data'!$E$2:$E$1489,$B$3,'Cleaned Data'!$F$2:$F$1489,$B$4,'Cleaned Data'!$G$2:$G$1489,$B$5,'Cleaned Data'!$O$2:$O$1489,"Delivered",'Cleaned Data'!$F$2:$F$1489,$A23) -> 107801 | D23: =IFERROR(C23/B23,0) -> 449.17083
A24: Fast Food | B24: =COUNTIFS('Cleaned Data'!$E$2:$E$1489,$B$3,'Cleaned Data'!$F$2:$F$1489,$B$4,'Cleaned Data'!$G$2:$G$1489,$B$5,'Cleaned Data'!$O$2:$O$1489,"Delivered",'Cleaned Data'!$F$2:$F$1489,$A24) -> 219 | C24: =SUMIFS('Cleaned Data'!$L$2:$L$1489,'Cleaned Data'!$E$2:$E$1489,$B$3,'Cleaned Data'!$F$2:$F$1489,$B$4,'Cleaned Data'!$G$2:$G$1489,$B$5,'Cleaned Data'!$O$2:$O$1489,"Delivered",'Cleaned Data'!$F$2:$F$1489,$A24) -> 83515 | D24: =IFERROR(C24/B24,0) -> 381.34703
A25: Pizza | B25: =COUNTIFS('Cleaned Data'!$E$2:$E$1489,$B$3,'Cleaned Data'!$F$2:$F$1489,$B$4,'Cleaned Data'!$G$2:$G$1489,$B$5,'Cleaned Data'!$O$2:$O$1489,"Delivered",'Cleaned Data'!$F$2:$F$1489,$A25) -> 189 | C25: =SUMIFS('Cleaned Data'!$L$2:$L$1489,'Cleaned Data'!$E$2:$E$1489,$B$3,'Cleaned Data'!$F$2:$F$1489,$B$4,'Cleaned Data'!$G$2:$G$1489,$B$5,'Cleaned Data'!$O$2:$O$1489,"Delivered",'Cleaned Data'!$F$2:$F$1489,$A25) -> 109913 | D25: =IFERROR(C25/B25,0) -> 581.55026
A26: Chinese | B26: =COUNTIFS('Cleaned Data'!$E$2:$E$1489,$B$3,'Cleaned Data'!$F$2:$F$1489,$B$4,'Cleaned Data'!$G$2:$G$1489,$B$5,'Cleaned Data'!$O$2:$O$1489,"Delivered",'Cleaned Data'!$F$2:$F$1489,$A26) -> 173 | C26: =SUMIFS('Cleaned Data'!$L$2:$L$1489,'Cleaned Data'!$E$2:$E$1489,$B$3,'Cleaned Data'!$F$2:$F$1489,$B$4,'Cleaned Data'!$G$2:$G$1489,$B$5,'Cleaned Data'!$O$2:$O$1489,"Delivered",'Cleaned Data'!$F$2:$F$1489,$A26) -> 74244 | D26: =IFERROR(C26/B26,0) -> 429.15607
A27: South Indian | B27: =COUNTIFS('Cleaned Data'!$E$2:$E$1489,$B$3,'Cleaned Data'!$F$2:$F$1489,$B$4,'Cleaned Data'!$G$2:$G$1489,$B$5,'Cleaned Data'!$O$2:$O$1489,"Delivered",'Cleaned Data'!$F$2:$F$1489,$A27) -> 147 | C27: =SUMIFS('Cleaned Data'!$L$2:$L$1489,'Cleaned Data'!$E$2:$E$1489,$B$3,'Cleaned Data'!$F$2:$F$1489,$B$4,'Cleaned Data'!$G$2:$G$1489,$B$5,'Cleaned Data'!$O$2:$O$1489,"Delivered",'Cleaned Data'!$F$2:$F$1489,$A27) -> 47916 | D27: =IFERROR(C27/B27,0) -> 325.95918
A28: Healthy | B28: =COUNTIFS('Cleaned Data'!$E$2:$E$1489,$B$3,'Cleaned Data'!$F$2:$F$1489,$B$4,'Cleaned Data'!$G$2:$G$1489,$B$5,'Cleaned Data'!$O$2:$O$1489,"Delivered",'Cleaned Data'!$F$2:$F$1489,$A28) -> 76 | C28: =SUMIFS('Cleaned Data'!$L$2:$L$1489,'Cleaned Data'!$E$2:$E$1489,$B$3,'Cleaned Data'!$F$2:$F$1489,$B$4,'Cleaned Data'!$G$2:$G$1489,$B$5,'Cleaned Data'!$O$2:$O$1489,"Delivered",'Cleaned Data'!$F$2:$F$1489,$A28) -> 36344 | D28: =IFERROR(C28/B28,0) -> 478.21053
A29: Desserts | B29: =COUNTIFS('Cleaned Data'!$E$2:$E$1489,$B$3,'Cleaned Data'!$F$2:$F$1489,$B$4,'Cleaned Data'!$G$2:$G$1489,$B$5,'Cleaned Data'!$O$2:$O$1489,"Delivered",'Cleaned Data'!$F$2:$F$1489,$A29) -> 68 | C29: =SUMIFS('Cleaned Data'!$L$2:$L$1489,'Cleaned Data'!$E$2:$E$1489,$B$3,'Cleaned Data'!$F$2:$F$1489,$B$4,'Cleaned Data'!$G$2:$G$1489,$B$5,'Cleaned Data'!$O$2:$O$1489,"Delivered",'Cleaned Data'!$F$2:$F$1489,$A29) -> 26003 | D29: =IFERROR(C29/B29,0) -> 382.39706
A30: Grand Total | B30: =SUM(B22:B29) -> 1405 | C30: =SUM(C22:C29) -> 625271 | D30: =IFERROR(C30/B30,0) -> 445.03274
A33: PIVOT 3 – Monthly Trend
A34: Month | B34: Orders | C34: Net Revenue (₹) | D34: Avg Order Value (₹)
A35: Jan | B35: =COUNTIFS('Cleaned Data'!$E$2:$E$1489,$B$3,'Cleaned Data'!$F$2:$F$1489,$B$4,'Cleaned Data'!$G$2:$G$1489,$B$5,'Cleaned Data'!$O$2:$O$1489,"Delivered",'Cleaned Data'!$C$2:$C$1489,$A35) -> 99 | C35: =SUMIFS('Cleaned Data'!$L$2:$L$1489,'Cleaned Data'!$E$2:$E$1489,$B$3,'Cleaned Data'!$F$2:$F$1489,$B$4,'Cleaned Data'!$G$2:$G$1489,$B$5,'Cleaned Data'!$O$2:$O$1489,"Delivered",'Cleaned Data'!$C$2:$C$1489,$A35) -> 43004 | D35: =IFERROR(C35/B35,0) -> 434.38384
A36: Feb | B36: =COUNTIFS('Cleaned Data'!$E$2:$E$1489,$B$3,'Cleaned Data'!$F$2:$F$1489,$B$4,'Cleaned Data'!$G$2:$G$1489,$B$5,'Cleaned Data'!$O$2:$O$1489,"Delivered",'Cleaned Data'!$C$2:$C$1489,$A36) -> 100 | C36: =SUMIFS('Cleaned Data'!$L$2:$L$1489,'Cleaned Data'!$E$2:$E$1489,$B$3,'Cleaned Data'!$F$2:$F$1489,$B$4,'Cleaned Data'!$G$2:$G$1489,$B$5,'Cleaned Data'!$O$2:$O$1489,"Delivered",'Cleaned Data'!$C$2:$C$1489,$A36) -> 43954 | D36: =IFERROR(C36/B36,0) -> 439.54
A37: Mar | B37: =COUNTIFS('Cleaned Data'!$E$2:$E$1489,$B$3,'Cleaned Data'!$F$2:$F$1489,$B$4,'Cleaned Data'!$G$2:$G$1489,$B$5,'Cleaned Data'!$O$2:$O$1489,"Delivered",'Cleaned Data'!$C$2:$C$1489,$A37) -> 118 | C37: =SUMIFS('Cleaned Data'!$L$2:$L$1489,'Cleaned Data'!$E$2:$E$1489,$B$3,'Cleaned Data'!$F$2:$F$1489,$B$4,'Cleaned Data'!$G$2:$G$1489,$B$5,'Cleaned Data'!$O$2:$O$1489,"Delivered",'Cleaned Data'!$C$2:$C$1489,$A37) -> 54175 | D37: =IFERROR(C37/B37,0) -> 459.11017
A38: Apr | B38: =COUNTIFS('Cleaned Data'!$E$2:$E$1489,$B$3,'Cleaned Data'!$F$2:$F$1489,$B$4,'Cleaned Data'!$G$2:$G$1489,$B$5,'Cleaned Data'!$O$2:$O$1489,"Delivered",'Cleaned Data'!$C$2:$C$1489,$A38) -> 87 | C38: =SUMIFS('Cleaned Data'!$L$2:$L$1489,'Cleaned Data'!$E$2:$E$1489,$B$3,'Cleaned Data'!$F$2:$F$1489,$B$4,'Cleaned Data'!$G$2:$G$1489,$B$5,'Cleaned Data'!$O$2:$O$1489,"Delivered",'Cleaned Data'!$C$2:$C$1489,$A38) -> 39431 | D38: =IFERROR(C38/B38,0) -> 453.22989
A39: May | B39: =COUNTIFS('Cleaned Data'!$E$2:$E$1489,$B$3,'Cleaned Data'!$F$2:$F$1489,$B$4,'Cleaned Data'!$G$2:$G$1489,$B$5,'Cleaned Data'!$O$2:$O$1489,"Delivered",'Cleaned Data'!$C$2:$C$1489,$A39) -> 106 | C39: =SUMIFS('Cleaned Data'!$L$2:$L$1489,'Cleaned Data'!$E$2:$E$1489,$B$3,'Cleaned Data'!$F$2:$F$1489,$B$4,'Cleaned Data'!$G$2:$G$1489,$B$5,'Cleaned Data'!$O$2:$O$1489,"Delivered",'Cleaned Data'!$C$2:$C$1489,$A39) -> 47501 | D39: =IFERROR(C39/B39,0) -> 448.12264
A40: Jun | B40: =COUNTIFS('Cleaned Data'!$E$2:$E$1489,$B$3,'Cleaned Data'!$F$2:$F$1489,$B$4,'Cleaned Data'!$G$2:$G$1489,$B$5,'Cleaned Data'!$O$2:$O$1489,"Delivered",'Cleaned Data'!$C$2:$C$1489,$A40) -> 122 | C40: =SUMIFS('Cleaned Data'!$L$2:$L$1489,'Cleaned Data'!$E$2:$E$1489,$B$3,'Cleaned Data'!$F$2:$F$1489,$B$4,'Cleaned Data'!$G$2:$G$1489,$B$5,'Cleaned Data'!$O$2:$O$1489,"Delivered",'Cleaned Data'!$C$2:$C$1489,$A40) -> 52426 | D40: =IFERROR(C40/B40,0) -> 429.72131
A41: Jul | B41: =COUNTIFS('Cleaned Data'!$E$2:$E$1489,$B$3,'Cleaned Data'!$F$2:$F$1489,$B$4,'Cleaned Data'!$G$2:$G$1489,$B$5,'Cleaned Data'!$O$2:$O$1489,"Delivered",'Cleaned Data'!$C$2:$C$1489,$A41) -> 123 | C41: =SUMIFS('Cleaned Data'!$L$2:$L$1489,'Cleaned Data'!$E$2:$E$1489,$B$3,'Cleaned Data'!$F$2:$F$1489,$B$4,'Cleaned Data'!$G$2:$G$1489,$B$5,'Cleaned Data'!$O$2:$O$1489,"Delivered",'Cleaned Data'!$C$2:$C$1489,$A41) -> 55728 | D41: =IFERROR(C41/B41,0) -> 453.07317
A42: Aug | B42: =COUNTIFS('Cleaned Data'!$E$2:$E$1489,$B$3,'Cleaned Data'!$F$2:$F$1489,$B$4,'Cleaned Data'!$G$2:$G$1489,$B$5,'Cleaned Data'!$O$2:$O$1489,"Delivered",'Cleaned Data'!$C$2:$C$1489,$A42) -> 126 | C42: =SUMIFS('Cleaned Data'!$L$2:$L$1489,'Cleaned Data'!$E$2:$E$1489,$B$3,'Cleaned Data'!$F$2:$F$1489,$B$4,'Cleaned Data'!$G$2:$G$1489,$B$5,'Cleaned Data'!$O$2:$O$1489,"Delivered",'Cleaned Data'!$C$2:$C$1489,$A42) -> 57779 | D42: =IFERROR(C42/B42,0) -> 458.56349
A43: Sep | B43: =COUNTIFS('Cleaned Data'!$E$2:$E$1489,$B$3,'Cleaned Data'!$F$2:$F$1489,$B$4,'Cleaned Data'!$G$2:$G$1489,$B$5,'Cleaned Data'!$O$2:$O$1489,"Delivered",'Cleaned Data'!$C$2:$C$1489,$A43) -> 124 | C43: =SUMIFS('Cleaned Data'!$L$2:$L$1489,'Cleaned Data'!$E$2:$E$1489,$B$3,'Cleaned Data'!$F$2:$F$1489,$B$4,'Cleaned Data'!$G$2:$G$1489,$B$5,'Cleaned Data'!$O$2:$O$1489,"Delivered",'Cleaned Data'!$C$2:$C$1489,$A43) -> 54456 | D43: =IFERROR(C43/B43,0) -> 439.16129
A44: Oct | B44: =COUNTIFS('Cleaned Data'!$E$2:$E$1489,$B$3,'Cleaned Data'!$F$2:$F$1489,$B$4,'Cleaned Data'!$G$2:$G$1489,$B$5,'Cleaned Data'!$O$2:$O$1489,"Delivered",'Cleaned Data'!$C$2:$C$1489,$A44) -> 130 | C44: =SUMIFS('Cleaned Data'!$L$2:$L$1489,'Cleaned Data'!$E$2:$E$1489,$B$3,'Cleaned Data'!$F$2:$F$1489,$B$4,'Cleaned Data'!$G$2:$G$1489,$B$5,'Cleaned Data'!$O$2:$O$1489,"Delivered",'Cleaned Data'!$C$2:$C$1489,$A44) -> 58826 | D44: =IFERROR(C44/B44,0) -> 452.50769
A45: Nov | B45: =COUNTIFS('Cleaned Data'!$E$2:$E$1489,$B$3,'Cleaned Data'!$F$2:$F$1489,$B$4,'Cleaned Data'!$G$2:$G$1489,$B$5,'Cleaned Data'!$O$2:$O$1489,"Delivered",'Cleaned Data'!$C$2:$C$1489,$A45) -> 127 | C45: =SUMIFS('Cleaned Data'!$L$2:$L$1489,'Cleaned Data'!$E$2:$E$1489,$B$3,'Cleaned Data'!$F$2:$F$1489,$B$4,'Cleaned Data'!$G$2:$G$1489,$B$5,'Cleaned Data'!$O$2:$O$1489,"Delivered",'Cleaned Data'!$C$2:$C$1489,$A45) -> 55791 | D45: =IFERROR(C45/B45,0) -> 439.29921
A46: Dec | B46: =COUNTIFS('Cleaned Data'!$E$2:$E$1489,$B$3,'Cleaned Data'!$F$2:$F$1489,$B$4,'Cleaned Data'!$G$2:$G$1489,$B$5,'Cleaned Data'!$O$2:$O$1489,"Delivered",'Cleaned Data'!$C$2:$C$1489,$A46) -> 143 | C46: =SUMIFS('Cleaned Data'!$L$2:$L$1489,'Cleaned Data'!$E$2:$E$1489,$B$3,'Cleaned Data'!$F$2:$F$1489,$B$4,'Cleaned Data'!$G$2:$G$1489,$B$5,'Cleaned Data'!$O$2:$O$1489,"Delivered",'Cleaned Data'!$C$2:$C$1489,$A46) -> 62200 | D46: =IFERROR(C46/B46,0) -> 434.96503
...

Sheet Charts
A1: CHARTS (linked to Pivot Tables – change Dashboard filters to update)

Sheet Dashboard
B1: 🍔 FOOD DELIVERY SALES DASHBOARD – 2025
B3: FILTERS (select from dropdowns)
B4: City | C4: All | E4: ◀ Pick a City / Cuisine / Customer Type – every KPI and chart updates instantly.
B5: Cuisine | C5: All | E5: Set all three back to 'All' to see the full year.
B6: Customer Type | C6: All
B8: NET REVENUE | D8: DELIVERED ORDERS | F8: AVG ORDER VALUE | H8: AVG DELIVERY TIME | J8: AVG RATING | L8: CANCELLATION RATE
B9: =SUMIFS('Cleaned Data'!$L$2:$L$1489,'Cleaned Data'!$E$2:$E$1489,'Pivot Tables'!$B$3,'Cleaned Data'!$F$2:$F$1489,'Pivot Tables'!$B$4,'Cleaned Data'!$G$2:$G$1489,'Pivot Tables'!$B$5) -> 625271 | D9: =COUNTIFS('Cleaned Data'!$E$2:$E$1489,'Pivot Tables'!$B$3,'Cleaned Data'!$F$2:$F$1489,'Pivot Tables'!$B$4,'Cleaned Data'!$G$2:$G$1489,'Pivot Tables'!$B$5,'Cleaned Data'!$O$2:$O$1489,"Delivered") -> 1405 | F9: =IFERROR(B9/D9,0) -> 445.03274 | H9: =IFERROR(AVERAGEIFS('Cleaned Data'!$M$2:$M$1489,'Cleaned Data'!$E$2:$E$1489,'Pivot Tables'!$B$3,'Cleaned Data'!$F$2:$F$1489,'Pivot Tables'!$B$4,'Cleaned Data'!$G$2:$G$1489,'Pivot Tables'!$B$5,'Cleaned Data'!$O$2:$O$1489,"Delivered"),0) -> 36.120996 | J9: =IFERROR(AVERAGEIFS('Cleaned Data'!$N$2:$N$1489,'Cleaned Data'!$E$2:$E$1489,'Pivot Tables'!$B$3,'Cleaned Data'!$F$2:$F$1489,'Pivot Tables'!$B$4,'Cleaned Data'!$G$2:$G$1489,'Pivot Tables'!$B$5,'Cleaned Data'!$O$2:$O$1489,"Delivered"),0) -> 4.2583271 | L9: =IFERROR(COUNTIFS('Cleaned Data'!$E$2:$E$1489,'Pivot Tables'!$B$3,'Cleaned Data'!$F$2:$F$1489,'Pivot Tables'!$B$4,'Cleaned Data'!$G$2:$G$1489,'Pivot Tables'!$B$5,'Cleaned Data'!$O$2:$O$1489,"Cancelled")/COUNTIFS('Cleaned Data'!$E$2:$E$1489,'Pivot Tables'!$B$3,'Cleaned Data'!$F$2:$F$1489,'Pivot Tables'!$B$4,'Cleaned Data'!$G$2:$G$1489,'Pivot Tables'!$B$5),0) -> 0.05577957
B63: Source: Cleaned Data (tblOrders) via Pivot Tables sheet. Dataset: simulated Indian food-delivery orders, Jan–Dec 2025.

Sheet Insights
A1: KEY INSIGHTS & OBSERVATIONS
A2: Figures below are for the full year with all filters = 'All'.
A4: 1 | B4: Revenue concentration: Bengaluru, Delhi and Mumbai together generate 63% of total net revenue (₹625,271); Bengaluru leads with ₹141,596.
A5: 2 | B5: Cuisine mix: North Indian is the top revenue cuisine (22% share), followed by Pizza (18%); Desserts contributes the least (4%).
A6: 3 | B6: Seasonality / growth: monthly revenue grew from ₹43,004 in Jan to a peak of ₹62,200 in Dec (lowest: Apr, ₹39,431), showing an overall upward demand trend through the year.
A7: 4 | B7: Weekend effect: Fri–Sun account for 48% of delivered orders although they are only 43% of days – a clear weekend demand spike worth staffing and promoting for.
A8: 5 | B8: Payments: UPI is the most used method (40% of orders), then Cash on Delivery (19%); Cash on Delivery still holds a notable share, adding cash-handling cost.
A9: 6 | B9: Delivery speed vs satisfaction: avg rating is 4.49 for ≤30 min deliveries, 4.24 for 31–45 min and 3.87 for >45 min – slower deliveries clearly lower ratings. Bengaluru is the slowest city (41.9 min avg).
A10: 7 | B10: Cancellations: overall cancellation rate is 5.6%; Bengaluru is highest at 7.0%, lowest in Kolkata (1.3%) – cities with longer delivery times tend to see more cancellations.
A11: 8 | B11: Customer type: Returning customers make up 62% of delivered orders with avg net order value ₹457 vs ₹426 for new customers (new customers receive heavier discounts).
A13: RECOMMENDATIONS
A14: ➜ | B14: Add riders / dark-kitchen capacity in the slowest cities to bring delivery time under 35 minutes.
A15: ➜ | B15: Run weekend-specific bundles for top cuisines (e.g., Biryani, Pizza) and weekday lunch offers to even out demand.
A16: ➜ | B16: Push UPI cashback and reduce COD share to cut cash-handling costs and cancellations.
A17: ➜ | B17: Convert new customers with first-order discounts but protect margin using minimum-order thresholds.
A19: DATA CLEANING LOG
A20: • | B20: Raw records: 1525 → Cleaned records: 1488
A21: • | B21: Removed 25 duplicate Order_IDs
A22: • | B22: Removed 12 rows with missing Order_Value
A23: • | B23: Filled 18 missing Payment_Method values with 'Unknown'
A24: • | B24: Standardised City names (trim/case; 'Bangalore' → 'Bengaluru') and Customer_Type case
A25: • | B25: Converted text dates (dd-mm-yyyy) to real Excel dates
A26: • | B26: Added Month, Weekday and Net_Revenue (=Order_Value − Discount + Delivery_Fee, 0 if cancelled) as formulas
A27: • | B27: Converted range into Excel Table 'tblOrders'
A28: • | B28: Dataset note: simulated Indian food-delivery data (1,500 orders, 2025). Swap in a Kaggle dataset by pasting into Cleaned Data table.
